âœ… Loaded environment variables from .env file
Detected Azure VM connection to: 4.246.178.26
Failed to setup Azure VM connection: Timeout connecting to Azure VM
Failed to initialize Kubernetes client: Timeout connecting to Azure VM
Failed to initialize cloud Kubernetes client: Timeout connecting to Azure VM
Traceback (most recent call last):
  File "/Users/adityavikram.d/Documents/Workspace/AIDF/ResourceManager/rm1/backend/providers/cloud_kubernetes_provider.py", line 124, in _generate_kubeconfig_from_vm
    result = subprocess.run(kubeconfig_cmd, capture_output=True, text=True, timeout=30)
             ^^^^^^^^^^^^^^^^^^^^^^^^^^^^^^^^^^^^^^^^^^^^^^^^^^^^^^^^^^^^^^^^^^^^^^^^^^
  File "/opt/anaconda3/lib/python3.12/subprocess.py", line 550, in run
    stdout, stderr = process.communicate(input, timeout=timeout)
                     ^^^^^^^^^^^^^^^^^^^^^^^^^^^^^^^^^^^^^^^^^^^
  File "/opt/anaconda3/lib/python3.12/subprocess.py", line 1209, in communicate
    stdout, stderr = self._communicate(input, endtime, timeout)
                     ^^^^^^^^^^^^^^^^^^^^^^^^^^^^^^^^^^^^^^^^^^
  File "/opt/anaconda3/lib/python3.12/subprocess.py", line 2116, in _communicate
    self._check_timeout(endtime, orig_timeout, stdout, stderr)
  File "/opt/anaconda3/lib/python3.12/subprocess.py", line 1253, in _check_timeout
    raise TimeoutExpired(
subprocess.TimeoutExpired: Command '['ssh', '-o', 'PubkeyAuthentication=no', '-o', 'PasswordAuthentication=yes', '-o', 'StrictHostKeyChecking=no', 'azureuser@4.246.178.26', 'cat ~/.kube/config']' timed out after 30 seconds

During handling of the above exception, another exception occurred:

Traceback (most recent call last):
  File "/Users/adityavikram.d/Documents/Workspace/AIDF/ResourceManager/rm1/backend/app.py", line 34, in <module>
    from server_manager import server_manager
  File "/Users/adityavikram.d/Documents/Workspace/AIDF/ResourceManager/rm1/backend/server_manager.py", line 13, in <module>
    from providers.cloud_kubernetes_provider import CloudKubernetesProvider
  File "/Users/adityavikram.d/Documents/Workspace/AIDF/ResourceManager/rm1/backend/providers/cloud_kubernetes_provider.py", line 463, in <module>
    cloud_kubernetes_provider = CloudKubernetesProvider() 
                                ^^^^^^^^^^^^^^^^^^^^^^^^^
  File "/Users/adityavikram.d/Documents/Workspace/AIDF/ResourceManager/rm1/backend/providers/cloud_kubernetes_provider.py", line 29, in __init__
    self._initialize_kubernetes_client()
  File "/Users/adityavikram.d/Documents/Workspace/AIDF/ResourceManager/rm1/backend/providers/cloud_kubernetes_provider.py", line 46, in _initialize_kubernetes_client
    self._setup_azure_vm_connection(azure_vm_ip)
  File "/Users/adityavikram.d/Documents/Workspace/AIDF/ResourceManager/rm1/backend/providers/cloud_kubernetes_provider.py", line 74, in _setup_azure_vm_connection
    kubeconfig_content = self._generate_kubeconfig_from_vm(vm_ip, vm_username, vm_ssh_key)
                         ^^^^^^^^^^^^^^^^^^^^^^^^^^^^^^^^^^^^^^^^^^^^^^^^^^^^^^^^^^^^^^^^^
  File "/Users/adityavikram.d/Documents/Workspace/AIDF/ResourceManager/rm1/backend/providers/cloud_kubernetes_provider.py", line 153, in _generate_kubeconfig_from_vm
    raise Exception("Timeout connecting to Azure VM")
Exception: Timeout connecting to Azure VM
